<?xml version="1.0"?>
<robot name="my_bot">

    <!-- 1. Base link (rigid body) -->
    <link name="base_link">
        <visual>
            <geometry>
                <box size="0.3 0.2 0.05" />
            </geometry>
            <material name="white">
                <color rgba="1 1 1 1" />
            </material>
        </visual>
    </link>

    <!-- 2. Left wheel -->
    <link name="left_wheel">
        <visual>
            <geometry>
                <cylinder radius="0.05" length="0.02" />
            </geometry>
        </visual>
    </link>
    <joint name="left_wheel_joint" type="continuous">
        <parent link="base_link" />
        <child link="left_wheel" />
        <origin xyz="0.0 0.1 0.025" rpy="1.5708 0 0" />
        <axis xyz="0 0 1" />
    </joint>

    <!-- 3. Right wheel -->
    <link name="right_wheel">
        <visual>
            <geometry>
                <cylinder radius="0.05" length="0.02" />
            </geometry>
        </visual>
    </link>
    <joint name="right_wheel_joint" type="continuous">
        <parent link="base_link" />
        <child link="right_wheel" />
        <origin xyz="0.0 -0.1 0.025" rpy="1.5708 0 0" />
        <axis xyz="0 0 1" />
    </joint>

</robot>